Workbook
Name FG: 'Seuil de rentabilité'!$C$4
Name MB_UV: 'Seuil de rentabilité'!$C$5
Name Prod1: #REF!
Name Prod10: #REF!
Name Prod2: #REF!
Name Prod3: #REF!
Name Prod4: #REF!
Name Prod5: #REF!
Name Prod6: #REF!
Name Prod7: #REF!
Name Prod8: #REF!
Name Prod9: #REF!

Sheet Intro
A2: INTRODUCTION
A5: Le fichier suivant découpe le plan financier de votre activité. Il va vous permettre de réaliser quel revenu vous pouvez espérer de votre activité.
A6: Soyez le plus précis possible avec vos estimations.
A8: 1) Attention! / Let Op! / Achtung!
A9: Seules ces cases "saumons" sont à remplir selon votre situation
B10: Toutes les autres cases se remplissent automatiquement => ne surtout pas les remplir sinon vous écrasez les formules => penser à revenir en arrière si besoin <CTRL> < Z>
A12: 2) Veuillez à vous projeter à la fin de vos 18 mois de test pour créer ce plan financier, nous parlerons donc de votre 1er mois d'activité en tant qu'indépendant avec votre propre numéro de TVA: soit 19 mois après le début de votre test.
A14: 3) Faites varier les hypothèses pour voir ce que cela donne sur votre rentabilité, et le revenu que vous pouvez tirer de l'activité. Vous pouvez créer autant de scénarios que vous le souhaitez pour tester l'impact économique de vos hypothèses: prix de vente, frais généraux...
A16: Ce fichier est mis à disposition des Candidats-Entrepreneurs de JYS

Sheet Investissement
B1: Investissements
B2: Les investissements dont vous avez absolument besoin pour démarrer votre activité.
B3: Ce que vous possédez déjà ne compte pas à ce stade. A moins que l'investissement soit récent et que vous ayez encore la facture. Dans ce cas il faut indiquer en prix d'achat le montant non amorti.
B5: Désignation | D5: Prix d'achat tvaC | E5: Prix d'achat Htva | F5: durée de l'amortissement | G5: durée de l'amortissement | H5: Montant mensuel de l'amortissement année 1 | I5: Montant mensuel de l'amortissement année 2 ou plus
C6: Unités: | D6: Euros | E6: Euros | F6: année | G6: mois | H6: Euros | I6: Euros
B7: Ordinateur | C7: 1 | D7: 1800 | E7: =SUM(D7/1.21) | F7: 3 | G7: =+F7*12 | H7: =E7*C7/G7 | I7: =H7 | J7: > | K7: Pour obtenir le montant Htva > montant tvaC/1,21 (pour TVA à 21%)
B8: Téléphone | C8: 0 | D8: 0 | E8: =SUM(D8/1.21) | F8: 3 | G8: =+F8*12 | H8: =E8*C8/G8 | I8: =H8 | J8: > | K8: Renseignez-vous sur internet concernant la durée d'amortissement
B9: Bureau | C9: 0 | D9: 0 | E9: =SUM(D9/1.21) | F9: 5 | G9: =+F9*12 | H9: =E9*C9/G9 | I9: =H9
B10: Chaises | C10: 0 | D10: 0 | E10: =SUM(D10/1.21) | F10: 5 | G10: =+F10*12 | H10: =E10*C10/G10 | I10: =H10
B11: Luminaires | C11: 0 | D11: 0 | E11: =SUM(D11/1.21) | F11: 3 | G11: =+F11*12 | H11: =E11*C11/G11 | I11: =H11
B12: Micro Cravate | C12: 0 | D12: 0 | E12: =SUM(D12/1.21) | F12: 3 | G12: =+F12*12 | H12: =E12*C12/G12 | I12: =H12
B13: Imprimantes | C13: 0 | D13: 0 | E13: =SUM(D13/1.21) | F13: 3 | G13: =+F13*12 | H13: =E13*C13/G13 | I13: =H13
B14: Identité visuelle du projet | C14: 0 | D14: 0 | E14: =SUM(D14/1.21) | F14: 3 | G14: =+F14*12 | H14: =E14*C14/G14 | I14: =H14
B15: Création Site Web | C15: 0 | D15: 0 | E15: =SUM(D15/1.21) | F15: 3 | G15: =+F15*12 | H15: =E15*C15/G15 | I15: =H15
C16: 0 | D16: 0 | E16: =SUM(D16/1.21) | F16: 3 | G16: =+F16*12 | H16: =E16*C16/G16 | I16: =H16
C17: 0 | D17: 0 | E17: =SUM(D17/1.21) | F17: 3 | G17: =+F17*12 | H17: =E17*C17/G17 | I17: =H17
C18: 0 | D18: 0 | E18: =SUM(D18/1.21) | F18: 3 | G18: =+F18*12 | H18: =E18*C18/G18 | I18: =H18
C19: 0 | D19: 0 | E19: =SUM(D19/1.21) | F19: 3 | G19: =+F19*12 | H19: =E19*C19/G19 | I19: =H19
C20: 0 | D20: 0 | E20: =SUM(D20/1.21) | F20: 3 | G20: =+F20*12 | H20: =E20*C20/G20 | I20: =H20
B21: TOTAL | E21: =SUM(E7:E20) | H21: =SUM(H7:H20) | I21: =SUM(I7:I20)
B23: INVESTISSEMENT = Matériel (outils, machine, mobilier, véhicule) que vous allez utiliser sur min 2 ans pour un montant supérieur à 250 euros HTVA (coût unitaire)
B24: Si vous désirez mettre un vehicule (2-3-4… roues) dans les investissements, renseignez-vous sur la partie déductible qui va dépendre de plusieurs paramètres.

Sheet Frais Généraux
B1: Frais généraux / frais de fonctionnement
B2: Les frais que vous devez effectuer pour faire tourner votre activité.
A4: PILATEF | B4: Désignation | D4: Coût/annuel HTVA | E4: Coût/Mois HTVA
B5: Publicité | C5: Hébergement | D5: =E5*12 | E5: 5 | F5: > | G5: Comment obtenir le montant Htva ? > montant tvaC/1,21
C6: Nom de domaine | D6: =E6*12 | E6: 2
C7: Mise à jour/maintenance site web | D7: =E7*12 | E7: 0
C8: impression Cartes de visite | D8: 100 | E8: =D8/12
C9: Pub Réseaux sociaux | D9: =E9*12 | E9: 0
B10: Intérêts des emprunts | D10: =E10*12 | E10: ='fond de roulement'!C18
B11: Loyer | D11: =E11*12 | E11: 0 | F11: > | G11: si propriétaire OU voir avec propriétaire car inscription dans bail. Sera calculé au prorata du métrage carré de la surface pro
B12: Assurances | C12: Responsabilité Civile et Jur Pro (Obligatoire) | D12: 425 | E12: =D12/12
C13: Revenu garanti (option) | D13: 0 | E13: =D13/12
C14: Incendie | D14: 0 | E14: =D14/12 | F14: > | G14: Sera calculé au prorata du métrage carré de la surface pro
C15: Pension complémentaire (PLCI) (option) | D15: 0 | E15: =D15/12
B16: Télécomunications | C16: GSM | D16: =E16*12 | E16: 15 | F16: > | G16: si 1 seul abonnement GSM: part pro = 75-80%. OU si abonnement exclusivement PRO: à reprendre à 100%
C17: Internet | D17: =E17*12 | E17: 10 | F17: > | G17: si 1 seul abonnement INTERNET: part pro = Sera calculé au prorata du métrage carré de la surface pro. OU si abonnement exclusivement PRO : à reprendre à 100%
B18: Energie | C18: Gaz et électricité | D18: =E18*12 | E18: 10 | F18: > | G18: si travail depuis le domicile: part pro de la facture = Sera calculé au prorata du métrage carré de la surface pro. OU si local exclusivement PRO: à reprendre à 100%
B19: Frais divers (tout ce qui sert à plus d'un client) | C19: Location de licence (Adobe, Canva, ChatGPT...) | D19: 600 | E19: =D19/12
C20: Fourniture de bureau | D20: =E20*12 | E20: 5
C21: Déplacements | D21: =E21*12 | E21: 25 | F21: > | G21: Voiture: 0,4290 € / km & Vélo: 0,24 €/km pour utilisation privé/pro ; STIB-TEC-DE LIJN-SNCB abonnement : 80% ; cartes 10 trajets: à 100% sur justificatifs
C22: Comptable | D22: 1100 | E22: =D22/12
C23: Formations | D23: 200 | E23: =D23/12
C24: Coworking | D24: 0 | E24: =D24/12
C25: Dépot de marque | D25: 0 | E25: =D25/12
D26: 0 | E26: =D26/12
D27: 0 | E27: =D27/12
D28: 0 | E28: =D28/12
D29: 0 | E29: =D29/12
B30: TOTAL | E30: =SUM(E5:E29)
B32: FRAIS GENERAUX = coûts engagés par une entreprise dans le cadre de ses activités quotidiennes : tous les frais de fonctionnement récurrents (ex : électricité, déplacements, communications, location assurances…) sauf les frais variables qui vont se retrouver dans le calcul de la marge brute à l’onglet suivant.

Sheet CA et Marge Brute
A2: Chiffre d'affaire, frais d'approvisionnement et marge brute
A4: Vos produits/services | B4: Prix de vente/ unité TVAC | C4: Choix TVA (0%, 6%, 12%, 21%) | D4: prix de vente/ unité HTVA | E4: frais d'approvisionnement par unité (HTVA) | F4: marge brute par unité de produit | G4: nbr moyen d'unités vendues par mois | H4: durée totale mensuelle restant disponible | I4: nbr unités vendues par an | J4: CA HTVA mensuel moyen | K4: frais d'appro moyen par mois | L4: marge brute mensuelle de ce produit par mois moyen | M4: CA HTVA annuel | N4: frais d'appro annuel | O4: marge brute annuelle de ce produit
H5: =SUM('Durée Prod'!G20) | J5: =SUM(J6:J15) | K5: =SUM(K6:K15) | L5: =SUM(L6:L15) | M5: =SUM(M6:M15) | N5: =SUM(N6:N15) | O5: =SUM(O6:O15) | Q5: TVA
A6: Site web ASBL (forfait site + formation + 3 mois support) | B6: 1500 | C6: 0 | D6: =B6/(1+C6) | E6: 0 | F6: =D6-E6 | G6: 0.92 | H6: =SUM('Durée Prod'!G3) | I6: =SUM(G6*12) | J6: =G6*D6 | K6: =G6*E6 | L6: =F6*G6 | M6: =J6*12 | N6: =K6*12 | O6: =L6*12 | Q6: 0
A7: Hébergement + nom de domaine (forfait annuel par site du parc) | B7: 100 | C7: 0 | D7: =B7/(1+C7) | E7: 30 | F7: =D7-E7 | G7: 1.25 | H7: =SUM('Durée Prod'!G4) | I7: =SUM(G7*12) | J7: =G7*D7 | K7: =G7*E7 | L7: =F7*G7 | M7: =J7*12 | N7: =K7*12 | O7: =L7*12 | Q7: 0.06
A8: App / outil de gestion sur mesure (CRM, subsides, inscriptions) | B8: 3000 | C8: 0 | D8: =B8/(1+C8) | E8: 0 | F8: =D8-E8 | G8: 0.17 | H8: =SUM('Durée Prod'!G5) | I8: =SUM(G8*12) | J8: =G8*D8 | K8: =G8*E8 | L8: =F8*G8 | M8: =J8*12 | N8: =K8*12 | O8: =L8*12 | Q8: 0.12
A9: Hébergement app de gestion (forfait annuel par app) | B9: 150 | C9: 0 | D9: =B9/(1+C9) | E9: 40 | F9: =D9-E9 | G9: 0.17 | H9: =SUM('Durée Prod'!G6) | I9: =SUM(G9*12) | J9: =G9*D9 | K9: =G9*E9 | L9: =F9*G9 | M9: =J9*12 | N9: =K9*12 | O9: =L9*12 | Q9: 0.21
A10: Produit/Service 5 | B10: 0 | C10: 0.21 | D10: =B10/(1+C10) | E10: 0 | F10: =D10-E10 | H10: =SUM('Durée Prod'!G7) | I10: =SUM(G10*12) | J10: =G10*D10 | K10: =G10*E10 | L10: =F10*G10 | M10: =J10*12 | N10: =K10*12 | O10: =L10*12
A11: Produit/Service 6 | B11: 0 | C11: 0.21 | D11: =B11/(1+C11) | E11: 0 | F11: =D11-E11 | H11: =SUM('Durée Prod'!G8) | I11: =SUM(G11*12) | J11: =G11*D11 | K11: =G11*E11 | L11: =F11*G11 | M11: =J11*12 | N11: =K11*12 | O11: =L11*12
A12: Produit/Service 7 | B12: 0 | C12: 0.21 | D12: =B12/(1+C12) | E12: 0 | F12: =D12-E12 | H12: =SUM('Durée Prod'!G9) | I12: =SUM(G12*12) | J12: =G12*D12 | K12: =G12*E12 | L12: =F12*G12 | M12: =J12*12 | N12: =K12*12 | O12: =L12*12
A13: Produit/Service 8 | B13: 0 | C13: 0.21 | D13: =B13/(1+C13) | E13: 0 | F13: =D13-E13 | H13: =SUM('Durée Prod'!G10) | I13: =SUM(G13*12) | J13: =G13*D13 | K13: =G13*E13 | L13: =F13*G13 | M13: =J13*12 | N13: =K13*12 | O13: =L13*12
A14: Produit/Service 9 | B14: 0 | C14: 0.21 | D14: =B14/(1+C14) | E14: 0 | F14: =D14-E14 | H14: =SUM('Durée Prod'!G11) | I14: =SUM(G14*12) | J14: =G14*D14 | K14: =G14*E14 | L14: =F14*G14 | M14: =J14*12 | N14: =K14*12 | O14: =L14*12
A15: Produit/Service 10 | B15: 0 | C15: 0.21 | D15: =B15/(1+C15) | E15: 0 | F15: =D15-E15 | H15: =SUM('Durée Prod'!G12) | I15: =SUM(G15*12) | J15: =G15*D15 | K15: =G15*E15 | L15: =F15*G15 | M15: =J15*12 | N15: =K15*12 | O15: =L15*12
A17: > Chaque projet doit définir ses unité de produits ou services. | E17: > Les frais d'approvisionnement englobent aussi les frais variables liés au niveau d'activité.

Sheet Durée Prod
B2: Durée de production | C2: Temps de production unitaire en heure | D2: nb d'unités ou de participants | E2: Unités vendues ou nb participants/mois | F2: Unités prestés/mois | G2: Temps de production total investi | H2: Marge Brute par heure
B3: ='CA et Marge Brute'!A6 | C3: 40 | D3: 1 | E3: ='CA et Marge Brute'!G6 | F3: =E3/D3 | G3: =C3*F3 | H3: =IF(F3=0,0,'CA et Marge Brute'!L6/'Durée Prod'!G3)
B4: ='CA et Marge Brute'!A7 | C4: 2 | D4: 1 | E4: ='CA et Marge Brute'!G7 | F4: =E4/D4 | G4: =C4*F4 | H4: =IF(F4=0,0,'CA et Marge Brute'!L7/'Durée Prod'!G4)
B5: ='CA et Marge Brute'!A8 | C5: 100 | D5: 1 | E5: ='CA et Marge Brute'!G8 | F5: =E5/D5 | G5: =C5*F5 | H5: =IF(F5=0,0,'CA et Marge Brute'!L8/'Durée Prod'!G5)
B6: ='CA et Marge Brute'!A9 | C6: 3 | D6: 1 | E6: ='CA et Marge Brute'!G9 | F6: =E6/D6 | G6: =C6*F6 | H6: =IF(F6=0,0,'CA et Marge Brute'!L9/'Durée Prod'!G6)
B7: ='CA et Marge Brute'!A10 | D7: 1 | E7: ='CA et Marge Brute'!G10 | F7: =E7/D7 | G7: =C7*F7 | H7: =IF(F7=0,0,'CA et Marge Brute'!L10/'Durée Prod'!G7)
B8: ='CA et Marge Brute'!A11 | D8: 1 | E8: ='CA et Marge Brute'!G11 | F8: =E8/D8 | G8: =C8*F8 | H8: =IF(F8=0,0,'CA et Marge Brute'!L11/'Durée Prod'!G8)
B9: ='CA et Marge Brute'!A12 | D9: 1 | E9: ='CA et Marge Brute'!G12 | F9: =E9/D9 | G9: =C9*F9 | H9: =IF(F9=0,0,'CA et Marge Brute'!L12/'Durée Prod'!G9)
B10: ='CA et Marge Brute'!A13 | D10: 1 | E10: ='CA et Marge Brute'!G13 | F10: =E10/D10 | G10: =C10*F10 | H10: =IF(F10=0,0,'CA et Marge Brute'!L13/'Durée Prod'!G10)
B11: ='CA et Marge Brute'!A14 | D11: 1 | E11: ='CA et Marge Brute'!G14 | F11: =E11/D11 | G11: =C11*F11 | H11: =IF(F11=0,0,'CA et Marge Brute'!L14/'Durée Prod'!G11)
B12: ='CA et Marge Brute'!A15 | D12: 1 | E12: ='CA et Marge Brute'!G15 | F12: =E12/D12 | G12: =C12*F12 | H12: =IF(F12=0,0,'CA et Marge Brute'!L15/'Durée Prod'!G12)
B13: Temps dédié à l'Administratif * | G13: 15 | H13: *
B14: Temps dédié à la Prospection* | G14: 15 | H14: *
B15: Temps dédié à la COM* | G15: 10 | H15: *
B16: Temps dédié à ,,,* | H16: *
B17: Temps dédié à ,,,* | H17: *
B18: Somme totale des H PREVUES | G18: =SUM(G3:G17)
B19: Heures dispo / mois (référent) * | C19: < 4,2 | G19: 100 | H19: > à complèter selon le temps de travail souhaité | K19: 168 = équivalent 40h/sem, 4,2semaines/mois = 1ETP
B20: Restent disponibles > | G20: =G19-G18 | K20: 134 = équivalent 32h/sem, 4,2semaines/mois = 4/5 ETP
K21: 100 = équivalent 24h/sem, 4,2semaines/mois = 3/5 ETP
B22: * Temps estimé en lancement de projet = +- 1/2 (admin + prospection + communication + … = heures invisibles) et +/- 1/2 facturable | K22: 68 = équivalent 16h/sem, 4,2semaines/mois = 1/2 ETP
B24: > Toutes les activités mentionnées dans votre BMC doivent être reprise dans ce fichier

Sheet Calcul rém indépendant
B1: Revenus de l'indépendant | D1: chiffres pour 2025
B2: Chiffre d'affaire mensuel moyen hors TVA
B3: Différentes approches à combiner éventuellement
B4: nombre d'heures prestées par mois
B5: tarif horaire
B6: tarif à la journée de 8h
B7: tarif à la pièce
B8: CA dans Jobyourself
B11: Calcul du net
B12: CA mensuel moyen | D12: ='CA et Marge Brute'!J5
B13: mois d'activités | C13: 11
B14: CA annuel | D14: =D12*C13
B15: % frais approvisionnement | C15: 0 | D15: =D14*C15
B16: % frais généraux (forfaitaire 20% CA) | C16: 0 | D16: =D14*C16
B17: ou Calcul approvisionnement annuel | D17: ='CA et Marge Brute'!K5*C13 | E17: sur nb de mois d'activité
B18: ou Calcul frais généraux annuel | D18: ='Frais Généraux'!E30*12 | E18: 12 mois
B19: Amortissement annuel (année 1) | D19: =Investissement!H21*12
B20: Résultat d'exploitation | D20: =D14-D15-D16-D17-D18-D19
E21: Principal
B22: INASTI entre 13.993,78 et 60.427,15 | C22: 0.205 | D22: =(D20*C22)+((D20*C22)*0.04) | E22: =715.64*4
B23: frais 4% guichet d'entreprise inclus | C23: par trimestre
B25: BASE imposable | D25: =+D20-D22
B27: IMPOTS sur base de | D27: =D25
B28: 15820 | C28: 0.25 | D28: =IF(D25<B28,D25*C28,3955)
B29: 27920 | C29: 0.4 | D29: =IF(D28=3955,IF((AND(D25>=B28,D25<B29)),(D25-B28)*C29,4840),0)
B30: 48320 | C30: 0.45 | D30: =IF(D29=4840,IF((AND(D25>=B29,D25<B30)),(D25-B29)*C30,5652),0)
B31: ≥ 48 320,00 € | C31: 0.5 | D31: =IF(D30=5652,IF((AND(D25>=B30,D25<B31)),(D25-B30)*C31,""),0)
B32: TOTAL provisoire IMPOTS | D32: =SUM(D28:D31)
B34: montant exonéré | D34: 0 | E34: *chiffre 2024
B35: conjoint idem
B36: montant exonéré/enfant
B37: Total quotités exemptées | D37: =SUM(D34:D36)
B38: Réduction impôt sur quotités exemptées
B39: =B28 | C39: 0.25 | D39: =IF(D37<B39,-D37*C39,-3955)
B40: =B29 | C40: 0.4 | D40: =IF(D39=-3955,IF((AND(D37>=B39,D37<B40)),-(D37-B39)*C40,-4840),0) | E40: =IF(D40=-3955,IF((AND(D37>=B39,D37<B41)),-(D37-B40)*C41,-4840),0)
B41: =B30 | C41: 0.45 | D41: =IF(D40=-4840,IF((AND(D37>=B40,D37<B41)),-(D37-B40)*C41,-5652),0)
B42: =B31 | C42: 0.5 | D42: =IF(D41=-5652,IF((AND(D37>=B41,D37>=B41)),-(D37-B41)*C42,""),0)
D43: =SUM(D39:D42)
B45: Total impôt | D45: =D32+D43
D46: =IF(D25=0,0,D45/D25)
...

Sheet fond de roulement
B2: Besoin d'argent comme fond de roulement
B3: Cette feuille calcule combien vous avez besoin d'argent pour démarrer l'activité, pour avancer l'argent avant que les clients ne payent.
B5: Investissements | C5: =Investissement!E21
B6: Fond de roulement pour frais généraux (hors intérêt) | C6: =(SUM('Frais Généraux'!E5:E9)+SUM('Frais Généraux'!E11:E29))*D6 | D6: 3 | E6: nbr de mois à pouvoir avancer des frais de fonctionnement
B7: 1er stock | C7: ='CA et Marge Brute'!K5*D7 | D7: 1 | E7: frais d'approvisionnement du premier mois
B8: (garantie locative) | C8: ='Frais Généraux'!E11*D8 | D8: 0 | E8: nbr de loyer en garantie
B9: (frais d'enregistrement > Ouverture n° TVA) | C9: 105
B10: (inauguration) | C10: 0
B11: Besoin d'argent | C11: =SUM(C5:C10)
B12: Apport personnel | C12: =C11*D12 | D12: 1
B13: Capital à emprunter | C13: =C11-C12
B15: Remboursement annuel | C15: =C13/D15 | D15: 1 | E15: durée du prêt (années)
B16: Remboursement mensuel | C16: =C15/D16 | D16: 12
B17: Intéret annuel | C17: =C13*D17 | D17: 0.06
B18: Intérets mensuels | C18: =C17/D16

Sheet Seuil de rentabilité
B2: Seuil de rentabilité mensuel du premier produit introduit dans l'onglet CA et frais d'appro
B4: Frais de fonctionnement / frais généraux | C4: ='Frais Généraux'!E30
B5: Marge brute par unité vendue | C5: ='CA et Marge Brute'!F6 | D5: (ici calculée sur un seul produit - produit 1 )
B6: Nombre de client/mois | C6: =C4/C5
B7: Nombre de client/semaine | C7: =C6/4
B8: Nombre de client/jour | C8: =C7/5
B10: Attention avec cela vous ne couvrez pas encore vos cotisations sociales,vos impôts et vos amortissements !!
A12: nbr de client | B12: Marge brute totale selon nbr de clients | C12: FG mensuel
A13: 1 | B13: =MB_UV*A13 | C13: =C4
A14: 2 | B14: =MB_UV*A14 | C14: =C13
A15: 3 | B15: =MB_UV*A15 | C15: =C14
A16: 4 | B16: =MB_UV*A16 | C16: =C15
A17: 5 | B17: =MB_UV*A17 | C17: =C16
A18: 6 | B18: =MB_UV*A18 | C18: =C17
A19: 7 | B19: =MB_UV*A19 | C19: =C18
A20: 8 | B20: =MB_UV*A20 | C20: =C19
A21: 9 | B21: =MB_UV*A21 | C21: =C20
A22: 10 | B22: =MB_UV*A22 | C22: =C21
A23: 11 | B23: =MB_UV*A23 | C23: =C22
A24: 12 | B24: =MB_UV*A24 | C24: =C23
A25: 13 | B25: =MB_UV*A25 | C25: =C24
... A50: 38 | B50: =MB_UV*A50 | C50: =C49
