Workbook
Name FG: 'Seuil de rentabilité'!$C$4
Name MB_UV: 'Seuil de rentabilité'!$C$5
Name Prod1: 'Frais d''approvisionnement'!$B$4
Name Prod10: 'Frais d''approvisionnement'!$T$4
Name Prod2: 'Frais d''approvisionnement'!$D$4
Name Prod3: 'Frais d''approvisionnement'!$F$4
Name Prod4: 'Frais d''approvisionnement'!$H$4
Name Prod5: 'Frais d''approvisionnement'!$J$4
Name Prod6: 'Frais d''approvisionnement'!$L$4
Name Prod7: 'Frais d''approvisionnement'!$N$4
Name Prod8: 'Frais d''approvisionnement'!$P$4
Name Prod9: 'Frais d''approvisionnement'!$R$4

Sheet Intro
A2: INTRODUCTION
A5: Le fichier suivant découpe le plan financier de votre activité. Il va vous permettre de réaliser quel revenu vous pouvez espérer de votre activité.
A6: Soyez le plus précis possible avec vos estimations.
A8: 1) Attention! / Let Op! / Achtung!
A9: Seules ces cases "saumons" sont à remplir selon votre situation
B10: Toutes les autres cases se remplissent automatiquement => ne surtout pas les remplir sinon vous écrasez les formules => penser à revenir en arrière si besoin <CTRL> < Z>
A12: 2) Veuillez à vous projeter à la fin de vos 18 mois de test pour créer ce plan financier, nous parlerons donc de votre 1er mois d'activité en tant qu'indépendant avec votre propre numéro de TVA: soit 19 mois après le début de votre test.
A14: 3) Faites varier les hypothèses pour voir ce que cela donne sur votre rentabilité, et le revenu que vous pouvez tirer de l'activité. Vous pouvez créer autant de scénarios que vous le souhaitez pour tester l'impact économique de vos hypothèses: prix de vente, frais généraux...
A16: Ce fichier est mis à disposition des Candidats-Entrepreneurs de JYS

Sheet Investissement
B1: Investissements
B2: Les investissements dont vous avez absolument besoin pour démarrer votre activité.
B3: Ce que vous possédez déjà ne compte pas à ce stade. A moins que l'investissement soit récent et que vous ayez encore la facture. Dans ce cas il faut indiquer en prix d'achat le montant non amorti.
B5: Désignation | D5: Prix d'achat tvaC | E5: Prix d'achat Htva | F5: durée de l'amortissement | G5: durée de l'amortissement | H5: Montant mensuel de l'amortissement année 1 | I5: Montant mensuel de l'amortissement année 2 ou plus
C6: Unités: | D6: Euros | E6: Euros | F6: année | G6: mois | H6: Euros | I6: Euros
B7: Ordinateur | C7: 0 | D7: 0 | E7: =SUM(D7/1.21) -> 0 | F7: 3 | G7: =+F7*12 -> 36 | H7: =E7*C7/G7 -> 0 | I7: =H7 -> 0 | J7: > | K7: Pour obtenir le montant Htva > montant tvaC/1,21 (pour TVA à 21%)
B8: Téléphone | C8: 0 | D8: 0 | E8: =SUM(D8/1.21) -> 0 | F8: 3 | G8: =+F8*12 -> 36 | H8: =E8*C8/G8 -> 0 | I8: =H8 -> 0 | J8: > | K8: Renseignez-vous sur internet concernant la durée d'amortissement
B9: Bureau | C9: 0 | D9: 0 | E9: =SUM(D9/1.21) -> 0 | F9: 5 | G9: =+F9*12 -> 60 | H9: =E9*C9/G9 -> 0 | I9: =H9 -> 0
B10: Chaises | C10: 0 | D10: 0 | E10: =SUM(D10/1.21) -> 0 | F10: 5 | G10: =+F10*12 -> 60 | H10: =E10*C10/G10 -> 0 | I10: =H10 -> 0
B11: Luminaires | C11: 0 | D11: 0 | E11: =SUM(D11/1.21) -> 0 | F11: 3 | G11: =+F11*12 -> 36 | H11: =E11*C11/G11 -> 0 | I11: =H11 -> 0
B12: Micro Cravate | C12: 0 | D12: 0 | E12: =SUM(D12/1.21) -> 0 | F12: 3 | G12: =+F12*12 -> 36 | H12: =E12*C12/G12 -> 0 | I12: =H12 -> 0
B13: Imprimantes | C13: 0 | D13: 0 | E13: =SUM(D13/1.21) -> 0 | F13: 3 | G13: =+F13*12 -> 36 | H13: =E13*C13/G13 -> 0 | I13: =H13 -> 0
B14: Identité visuelle du projet | C14: 0 | D14: 0 | E14: =SUM(D14/1.21) -> 0 | F14: 3 | G14: =+F14*12 -> 36 | H14: =E14*C14/G14 -> 0 | I14: =H14 -> 0
B15: Création Site Web | C15: 0 | D15: 0 | E15: =SUM(D15/1.21) -> 0 | F15: 3 | G15: =+F15*12 -> 36 | H15: =E15*C15/G15 -> 0 | I15: =H15 -> 0
C16: 0 | D16: 0 | E16: 0 | F16: 3 | G16: =+F16*12 -> 36 | H16: =E16*C16/G16 -> 0 | I16: =H16 -> 0
C17: 1 | D17: 0 | E17: =SUM(D17/1.21) -> 0 | F17: 3 | G17: =+F17*12 -> 36 | H17: =E17*C17/G17 -> 0 | I17: =H17 -> 0
C18: 0 | D18: 0 | E18: =SUM(D18/1.21) -> 0 | F18: 3 | G18: =+F18*12 -> 36 | H18: =E18*C18/G18 -> 0 | I18: =H18 -> 0
C19: 0 | D19: 0 | E19: =SUM(D19/1.21) -> 0 | F19: 3 | G19: =+F19*12 -> 36 | H19: =E19*C19/G19 -> 0 | I19: =H19 -> 0
C20: 0 | D20: 0 | E20: =SUM(D20/1.21) -> 0 | F20: 3 | G20: =+F20*12 -> 36 | H20: =E20*C20/G20 -> 0 | I20: =H20 -> 0
B21: TOTAL | E21: =SUM(E7:E20) -> 0 | H21: =SUM(H7:H20) -> 0 | I21: =SUM(I7:I20) -> 0
B23: INVESTISSEMENT = Matériel (outils, machine, mobilier, véhicule) que vous allez utiliser sur min 2 ans pour un montant supérieur à 250 euros HTVA (coût unitaire)
B24: Si vous désirez mettre un vehicule (2-3-4… roues) dans les investissements, renseignez-vous sur la partie déductible qui va dépendre de plusieurs paramètres.

Sheet Frais Généraux
B1: Frais généraux / frais de fonctionnement
B2: Les frais que vous devez effectuer pour faire tourner votre activité.
A4: PILATEF | B4: Désignation | D4: Coût/annuel HTVA | E4: Coût/Mois HTVA
B5: Publicité | C5: Hébergement | D5: =E5*12 -> 0 | E5: 0 | F5: > | G5: Comment obtenir le montant Htva ? > montant tvaC/1,21
C6: Nom de domaine | D6: =E6*12 -> 0 | E6: 0
C7: Mise à jour/maintenance site web | D7: =E7*12 -> 0 | E7: 0
C8: impression Cartes de visite | D8: 0 | E8: =D8/12 -> 0
C9: Pub Réseaux sociaux | D9: =E9*12 -> 0 | E9: 0
B10: Intérêts des emprunts | D10: =E10*12 -> 0 | E10: ='fond de roulement'!C18 -> 0
B11: Loyer | D11: =E11*12 -> 0 | E11: 0 | F11: > | G11: si propriétaire OU voir avec propriétaire car inscription dans bail. Sera calculé au prorata du métrage carré de la surface pro
B12: Assurances | C12: Responsabilité Civile et Jur Pro (Obligatoire) | D12: 0 | E12: =D12/12 -> 0
C13: Revenu garanti (option) | D13: 0 | E13: =D13/12 -> 0
C14: Incendie | D14: 0 | E14: =D14/12 -> 0 | F14: > | G14: Sera calculé au prorata du métrage carré de la surface pro
C15: Pension complémentaire (PLCI) (option) | D15: 0 | E15: =D15/12 -> 0
B16: Télécomunications | C16: GSM | D16: =E16*12 -> 0 | E16: 0 | F16: > | G16: si 1 seul abonnement GSM: part pro = 75-80%. OU si abonnement exclusivement PRO: à reprendre à 100%
C17: Internet | D17: =E17*12 -> 0 | E17: 0 | F17: > | G17: si 1 seul abonnement INTERNET: part pro = Sera calculé au prorata du métrage carré de la surface pro. OU si abonnement exclusivement PRO : à reprendre à 100%
B18: Energie | C18: Gaz et électricité | D18: =E18*12 -> 0 | E18: 0 | F18: > | G18: si travail depuis le domicile: part pro de la facture = Sera calculé au prorata du métrage carré de la surface pro. OU si local exclusivement PRO: à reprendre à 100%
B19: Frais divers (tout ce qui sert à plus d'un client) | C19: Location de licence (Adobe, Canva, ChatGPT...) | D19: 0 | E19: =D19/12 -> 0
C20: Fourniture de bureau | D20: =E20*12 -> 0 | E20: 0
C21: Déplacements | D21: =E21*12 -> 0 | E21: 0 | F21: > | G21: Voiture: 0,4290 € / km & Vélo: 0,24 €/km pour utilisation privé/pro ; STIB-TEC-DE LIJN-SNCB abonnement : 80% ; cartes 10 trajets: à 100% sur justificatifs
C22: Comptable | D22: 0 | E22: =D22/12 -> 0
C23: Formations | D23: 0 | E23: =D23/12 -> 0
C24: Coworking | D24: 0 | E24: =D24/12 -> 0
C25: Dépot de marque | D25: 0 | E25: =D25/12 -> 0
D26: 0 | E26: =D26/12 -> 0
D27: 0 | E27: =D27/12 -> 0
D28: 0 | E28: =D28/12 -> 0
D29: 0 | E29: =D29/12 -> 0
B30: TOTAL | E30: =SUM(E5:E29) -> 0
B32: FRAIS GENERAUX = coûts engagés par une entreprise dans le cadre de ses activités quotidiennes : tous les frais de fonctionnement récurrents (ex : électricité, déplacements, communications, location assurances…) sauf les frais variables qui vont se retrouver dans le calcul de la marge brute à l’onglet suivant.

Sheet Frais d'approvisionnement
B2: Frais d'approvisionnement HTVA par produit
B3: Produits
B4: Produit 1 | D4: Produit 2 | F4: Produit 3 | H4: Produit 4 | J4: Produit 5 | L4: Produit 6 | N4: Produit 7 | P4: Produit 8 | R4: Produit 9 | T4: Produit 10
B5: Type de frais | C5: Frais HTVA | D5: Type de frais | E5: Frais HTVA | F5: Type de frais | G5: Frais HTVA | H5: Type de frais | I5: Frais HTVA | J5: Type de frais | K5: Frais HTVA | L5: Type de frais | M5: Frais HTVA | N5: Type de frais | O5: Frais HTVA | P5: Type de frais | Q5: Frais HTVA | R5: Type de frais | S5: Frais HTVA | T5: Type de frais | U5: Frais HTVA
C6: =SUM(C7:C27) -> 0 | E6: =SUM(E7:E27) -> 0 | G6: =SUM(G7:G27) -> 0 | I6: =SUM(I7:I27) -> 0 | K6: =SUM(K7:K27) -> 0 | M6: =SUM(M7:M27) -> 0 | O6: =SUM(O7:O27) -> 0 | Q6: =SUM(Q7:Q27) -> 0 | S6: =SUM(S7:S27) -> 0 | U6: =SUM(U7:U27) -> 0
B30: > Les frais d'approvisionnement englobent aussi les frais variables liés au niveau d'activité.

Sheet CA et Marge Brute
A2: Chiffre d'affaire, frais d'approvisionnement et marge brute
A4: Vos produits | B4: Prix de vente/ unité TVAC | C4: Choix TVA (0%, 6%, 12%, 21%) | D4: prix de vente/ unité HTVA | E4: frais d'approvisionnement par unité (HTVA) | F4: marge brute par unité de produit | G4: nbr moyen d'unités vendues par mois | H4: durée totale mensuelle restant disponible | I4: nbr unités vendues par an | J4: CA HTVA mensuel moyen | K4: frais d'appro moyen par mois | L4: marge brute mensuelle de ce produit par mois moyen | M4: CA HTVA annuel | N4: frais d'appro annuel | O4: marge brute annuelle de ce produit
H5: =SUM('Durée Prod'!G20) -> 93 | J5: =SUM(J6:J15) -> 0 | K5: =SUM(K6:K15) -> 0 | L5: =SUM(L6:L15) -> 0 | M5: =SUM(M6:M15) -> 0 | N5: =SUM(N6:N15) -> 0 | O5: =SUM(O6:O15) -> 0 | Q5: TVA
A6: =Prod1 -> Produit 1 | B6: 0 | C6: 0.21 | D6: =B6/(1+C6) -> 0 | E6: ='Frais d''approvisionnement'!C6 -> 0 | F6: =D6-E6 -> 0 | H6: =SUM('Durée Prod'!G3) -> 0 | I6: =SUM(G6*12) -> 0 | J6: =G6*D6 -> 0 | K6: =G6*E6 -> 0 | L6: =F6*G6 -> 0 | M6: =J6*12 -> 0 | N6: =K6*12 -> 0 | O6: =L6*12 -> 0 | Q6: 0
A7: =Prod2 -> Produit 2 | B7: 0 | C7: 0.21 | D7: =B7/(1+C7) -> 0 | E7: ='Frais d''approvisionnement'!E6 -> 0 | F7: =D7-E7 -> 0 | H7: =SUM('Durée Prod'!G4) -> 0 | I7: =SUM(G7*12) -> 0 | J7: =G7*D7 -> 0 | K7: =G7*E7 -> 0 | L7: =F7*G7 -> 0 | M7: =J7*12 -> 0 | N7: =K7*12 -> 0 | O7: =L7*12 -> 0 | Q7: 0.06
A8: =Prod3 -> Produit 3 | B8: 0 | C8: 0.21 | D8: =B8/(1+C8) -> 0 | E8: ='Frais d''approvisionnement'!G6 -> 0 | F8: =D8-E8 -> 0 | H8: =SUM('Durée Prod'!G5) -> 0 | I8: =SUM(G8*12) -> 0 | J8: =G8*D8 -> 0 | K8: =G8*E8 -> 0 | L8: =F8*G8 -> 0 | M8: =J8*12 -> 0 | N8: =K8*12 -> 0 | O8: =L8*12 -> 0 | Q8: 0.12
A9: =Prod4 -> Produit 4 | B9: 0 | C9: 0.21 | D9: =B9/(1+C9) -> 0 | E9: ='Frais d''approvisionnement'!I6 -> 0 | F9: =D9-E9 -> 0 | H9: =SUM('Durée Prod'!G6) -> 0 | I9: =SUM(G9*12) -> 0 | J9: =G9*D9 -> 0 | K9: =G9*E9 -> 0 | L9: =F9*G9 -> 0 | M9: =J9*12 -> 0 | N9: =K9*12 -> 0 | O9: =L9*12 -> 0 | Q9: 0.21
A10: =Prod5 -> Produit 5 | B10: 0 | C10: 0.21 | D10: =B10/(1+C10) -> 0 | E10: ='Frais d''approvisionnement'!K6 -> 0 | F10: =D10-E10 -> 0 | H10: =SUM('Durée Prod'!G7) -> 0 | I10: =SUM(G10*12) -> 0 | J10: =G10*D10 -> 0 | K10: =G10*E10 -> 0 | L10: =F10*G10 -> 0 | M10: =J10*12 -> 0 | N10: =K10*12 -> 0 | O10: =L10*12 -> 0
A11: =Prod6 -> Produit 6 | B11: 0 | C11: 0.21 | D11: =B11/(1+C11) -> 0 | E11: ='Frais d''approvisionnement'!M6 -> 0 | F11: =D11-E11 -> 0 | H11: =SUM('Durée Prod'!G8) -> 0 | I11: =SUM(G11*12) -> 0 | J11: =G11*D11 -> 0 | K11: =G11*E11 -> 0 | L11: =F11*G11 -> 0 | M11: =J11*12 -> 0 | N11: =K11*12 -> 0 | O11: =L11*12 -> 0
A12: =Prod7 -> Produit 7 | B12: 0 | C12: 0.21 | D12: =B12/(1+C12) -> 0 | E12: ='Frais d''approvisionnement'!O6 -> 0 | F12: =D12-E12 -> 0 | H12: =SUM('Durée Prod'!G9) -> 0 | I12: =SUM(G12*12) -> 0 | J12: =G12*D12 -> 0 | K12: =G12*E12 -> 0 | L12: =F12*G12 -> 0 | M12: =J12*12 -> 0 | N12: =K12*12 -> 0 | O12: =L12*12 -> 0
A13: =Prod8 -> Produit 8 | B13: 0 | C13: 0.21 | D13: =B13/(1+C13) -> 0 | E13: ='Frais d''approvisionnement'!Q6 -> 0 | F13: =D13-E13 -> 0 | H13: =SUM('Durée Prod'!G10) -> 0 | I13: =SUM(G13*12) -> 0 | J13: =G13*D13 -> 0 | K13: =G13*E13 -> 0 | L13: =F13*G13 -> 0 | M13: =J13*12 -> 0 | N13: =K13*12 -> 0 | O13: =L13*12 -> 0
A14: =Prod9 -> Produit 9 | B14: 0 | C14: 0.21 | D14: =B14/(1+C14) -> 0 | E14: ='Frais d''approvisionnement'!S6 -> 0 | F14: =D14-E14 -> 0 | H14: =SUM('Durée Prod'!G11) -> 0 | I14: =SUM(G14*12) -> 0 | J14: =G14*D14 -> 0 | K14: =G14*E14 -> 0 | L14: =F14*G14 -> 0 | M14: =J14*12 -> 0 | N14: =K14*12 -> 0 | O14: =L14*12 -> 0
A15: =Prod10 -> Produit 10 | B15: 0 | C15: 0.21 | D15: =B15/(1+C15) -> 0 | E15: ='Frais d''approvisionnement'!U6 -> 0 | F15: =D15-E15 -> 0 | H15: =SUM('Durée Prod'!G12) -> 0 | I15: =SUM(G15*12) -> 0 | J15: =G15*D15 -> 0 | K15: =G15*E15 -> 0 | L15: =F15*G15 -> 0 | M15: =J15*12 -> 0 | N15: =K15*12 -> 0 | O15: =L15*12 -> 0
A17: > Chaque projet doit définir ses unités de produits ou services.

Sheet Durée Prod
B2: Durée de production | C2: Temps de production unitaire en heure | D2: nb d'unités ou de participants | E2: Unités vendues ou nb participants/mois | F2: Unités prestés/mois | G2: Temps de production total investi | H2: Marge Brute par heure
B3: =Prod1 -> Produit 1 | D3: 1 | E3: ='CA et Marge Brute'!G6 -> 0 | F3: =E3/D3 -> 0 | G3: =C3*F3 -> 0 | H3: =IF(F3=0,0,'CA et Marge Brute'!L6/'Durée Prod'!G3) -> 0
B4: =Prod2 -> Produit 2 | D4: 1 | E4: ='CA et Marge Brute'!G7 -> 0 | F4: =E4/D4 -> 0 | G4: =C4*F4 -> 0 | H4: =IF(F4=0,0,'CA et Marge Brute'!L7/'Durée Prod'!G4) -> 0
B5: =Prod3 -> Produit 3 | D5: 1 | E5: ='CA et Marge Brute'!G8 -> 0 | F5: =E5/D5 -> 0 | G5: =C5*F5 -> 0 | H5: =IF(F5=0,0,'CA et Marge Brute'!L8/'Durée Prod'!G5) -> 0
B6: =Prod4 -> Produit 4 | D6: 1 | E6: ='CA et Marge Brute'!G9 -> 0 | F6: =E6/D6 -> 0 | G6: =C6*F6 -> 0 | H6: =IF(F6=0,0,'CA et Marge Brute'!L9/'Durée Prod'!G6) -> 0
B7: =Prod5 -> Produit 5 | D7: 1 | E7: ='CA et Marge Brute'!G10 -> 0 | F7: =E7/D7 -> 0 | G7: =C7*F7 -> 0 | H7: =IF(F7=0,0,'CA et Marge Brute'!L10/'Durée Prod'!G7) -> 0
B8: =Prod6 -> Produit 6 | D8: 1 | E8: ='CA et Marge Brute'!G11 -> 0 | F8: =E8/D8 -> 0 | G8: =C8*F8 -> 0 | H8: =IF(F8=0,0,'CA et Marge Brute'!L11/'Durée Prod'!G8) -> 0
B9: =Prod7 -> Produit 7 | D9: 1 | E9: ='CA et Marge Brute'!G12 -> 0 | F9: =E9/D9 -> 0 | G9: =C9*F9 -> 0 | H9: =IF(F9=0,0,'CA et Marge Brute'!L12/'Durée Prod'!G9) -> 0
B10: =Prod8 -> Produit 8 | D10: 1 | E10: ='CA et Marge Brute'!G13 -> 0 | F10: =E10/D10 -> 0 | G10: =C10*F10 -> 0 | H10: =IF(F10=0,0,'CA et Marge Brute'!L13/'Durée Prod'!G10) -> 0
B11: =Prod9 -> Produit 9 | D11: 1 | E11: ='CA et Marge Brute'!G14 -> 0 | F11: =E11/D11 -> 0 | G11: =C11*F11 -> 0 | H11: =IF(F11=0,0,'CA et Marge Brute'!L14/'Durée Prod'!G11) -> 0
B12: =Prod10 -> Produit 10 | D12: 1 | E12: ='CA et Marge Brute'!G15 -> 0 | F12: =E12/D12 -> 0 | G12: =C12*F12 -> 0 | H12: =IF(F12=0,0,'CA et Marge Brute'!L15/'Durée Prod'!G12) -> 0
B13: Temps dédié à l'Administratif * | G13: 25 | H13: *
B14: Temps dédié à la Prospection * | G14: 25 | H14: *
B15: Temps dédié à la COM * | G15: 25 | H15: *
B16: Temps dédié à ...* | H16: *
B17: Temps dédié à ,,,* | H17: *
B18: Somme totale des H PREVUES | G18: =SUM(G3:G17) -> 75
B19: Heures dispo / mois (référent) * | C19: < 4,2 | G19: 168 | H19: > à complèter selon le temps de travail souhaité | K19: 168 = équivalent 40h/sem, 4,2semaines/mois = 1ETP
B20: Restent disponibles > | G20: =G19-G18 -> 93 | K20: 134 = équivalent 32h/sem, 4,2semaines/mois = 4/5 ETP
K21: 100 = équivalent 24h/sem, 4,2semaines/mois = 3/5 ETP
B22: * Temps estimé en lancement de projet = +- 1/2 (admin + prospection + communication + … = heures invisibles) et +/- 1/2 facturable | K22: 68 = équivalent 16h/sem, 4,2semaines/mois = 1/2 ETP
B24: > Toutes les activités mentionnées dans votre BMC doivent être reprise dans ce fichier

Sheet Calcul rém indépendant
B1: Revenus de l'indépendant | D1: chiffres pour 2025
B2: Chiffre d'affaire mensuel moyen hors TVA
B3: Différentes approches à combiner éventuellement
B4: nombre d'heures prestées par mois
B5: tarif horaire
B6: tarif à la journée de 8h
B7: tarif à la pièce
B8: CA dans Jobyourself
B11: Calcul du net
B12: CA mensuel moyen | D12: ='CA et Marge Brute'!J5 -> 0
B13: mois d'activités | C13: 11
B14: CA annuel | D14: =D12*C13 -> 0
B15: % frais approvisionnement | C15: 0 | D15: =D14*C15 -> 0
B16: % frais généraux (forfaitaire 20% CA) | C16: 0 | D16: =D14*C16 -> 0
B17: ou Calcul approvisionnement annuel | D17: ='CA et Marge Brute'!K5*C13 -> 0 | E17: sur nb de mois d'activité
B18: ou Calcul frais généraux annuel | D18: ='Frais Généraux'!E30*12 -> 0 | E18: 12 mois
B19: Amortissement annuel (année 1) | D19: =Investissement!H21*12 -> 0
B20: Résultat d'exploitation | D20: =D14-D15-D16-D17-D18-D19 -> 0
E21: Principal
B22: INASTI entre 13.993,78 et 60.427,15 | C22: 0.205 | D22: =(D20*C22)+((D20*C22)*0.04) -> 0 | E22: =715.64*4 -> 2862.56
B23: frais 4% guichet d'entreprise inclus | C23: par trimestre
B25: BASE imposable | D25: =+D20-D22 -> 0
B27: IMPOTS sur base de | D27: =D25 -> 0
B28: 15820 | C28: 0.25 | D28: =IF(D25<B28,D25*C28,3955) -> 0
B29: 27920 | C29: 0.4 | D29: =IF(D28=3955,IF((AND(D25>=B28,D25<B29)),(D25-B28)*C29,4840),0) -> 0
B30: 48320 | C30: 0.45 | D30: =IF(D29=4840,IF((AND(D25>=B29,D25<B30)),(D25-B29)*C30,5652),0) -> 0
B31: ≥ 48 320,00 € | C31: 0.5 | D31: =IF(D30=5652,IF((AND(D25>=B30,D25<B31)),(D25-B30)*C31,""),0) -> 0
B32: TOTAL provisoire IMPOTS | D32: =SUM(D28:D31) -> 0
B34: montant exonéré | D34: 10160 | E34: *chiffre 2024
B35: conjoint idem
B36: montant exonéré/enfant
B37: Total quotités exemptées | D37: =SUM(D34:D36) -> 10160
B38: Réduction impôt sur quotités exemptées
B39: =B28 -> 15820 | C39: 0.25 | D39: =IF(D37<B39,-D37*C39,-3955) -> -2540
B40: =B29 -> 27920 | C40: 0.4 | D40: =IF(D39=-3955,IF((AND(D37>=B39,D37<B40)),-(D37-B39)*C40,-4840),0) -> 0 | E40: =IF(D40=-3955,IF((AND(D37>=B39,D37<B41)),-(D37-B40)*C41,-4840),0) -> 0
B41: =B30 -> 48320 | C41: 0.45 | D41: =IF(D40=-4840,IF((AND(D37>=B40,D37<B41)),-(D37-B40)*C41,-5652),0) -> 0
B42: =B31 -> ≥ 48 320,00 € | C42: 0.5 | D42: =IF(D41=-5652,IF((AND(D37>=B41,D37>=B41)),-(D37-B41)*C42,""),0) -> 0
D43: =SUM(D39:D42) -> -2540
B45: Total impôt | D45: =D32+D43 -> -2540
D46: =IF(D25=0,0,D45/D25) -> 0
...

Sheet fond de roulement
B2: Besoin d'argent comme fond de roulement
B3: Cette feuille calcule combien vous avez besoin d'argent pour démarrer l'activité, pour avancer l'argent avant que les clients ne payent.
B5: Investissements | C5: =Investissement!E21 -> 0
B6: Fond de roulement pour frais généraux (hors intérêt) | C6: =(SUM('Frais Généraux'!E5:E9)+SUM('Frais Généraux'!E11:E29))*D6 -> 0 | D6: 3 | E6: nbr de mois à pouvoir avancer des frais de fonctionnement
B7: 1er stock | C7: ='CA et Marge Brute'!K5*D7 -> 0 | D7: 1 | E7: frais d'approvisionnement du premier mois
B8: (garantie locative) | C8: ='Frais Généraux'!E11*D8 -> 0 | D8: 0 | E8: nbr de loyer en garantie
B9: (frais d'enregistrement > Ouverture n° TVA) | C9: 0
B10: (inauguration) | C10: 0
B11: Besoin d'argent | C11: =SUM(C5:C10) -> 0
B12: Apport personnel | C12: =C11*D12 -> 0 | D12: 1
B13: Capital à emprunter | C13: =C11-C12 -> 0
B15: Remboursement annuel | C15: =C13/D15 -> 0 | D15: 1 | E15: durée du prêt (années)
B16: Remboursement mensuel | C16: =C15/D16 -> 0 | D16: 12
B17: Intéret annuel | C17: =C13*D17 -> 0 | D17: 0.06
B18: Intérets mensuels | C18: =C17/D16 -> 0

Sheet Seuil de rentabilité
B2: Seuil de rentabilité mensuel du premier produit introduit dans l'onglet CA et frais d'appro
B4: Frais de fonctionnement / frais généraux | C4: ='Frais Généraux'!E30 -> 0
B5: Marge brute par unité vendue | C5: ='CA et Marge Brute'!F6 -> 0 | D5: (ici calculée sur un seul produit - produit 1 )
B6: Nombre de client/mois | C6: =C4/C5 -> #DIV/0!
B7: Nombre de client/semaine | C7: =C6/4 -> #DIV/0!
B8: Nombre de client/jour | C8: =C7/5 -> #DIV/0!
B10: Attention avec cela vous ne couvrez pas encore vos cotisations sociales,vos impôts et vos amortissements !!
A12: nbr de client | B12: Marge brute totale selon nbr de clients | C12: FG mensuel
A13: 1 | B13: =MB_UV*A13 -> 0 | C13: =C4 -> 0
A14: 2 | B14: =MB_UV*A14 -> 0 | C14: =C13 -> 0
A15: 3 | B15: =MB_UV*A15 -> 0 | C15: =C14 -> 0
A16: 4 | B16: =MB_UV*A16 -> 0 | C16: =C15 -> 0
A17: 5 | B17: =MB_UV*A17 -> 0 | C17: =C16 -> 0
A18: 6 | B18: =MB_UV*A18 -> 0 | C18: =C17 -> 0
A19: 7 | B19: =MB_UV*A19 -> 0 | C19: =C18 -> 0
A20: 8 | B20: =MB_UV*A20 -> 0 | C20: =C19 -> 0
A21: 9 | B21: =MB_UV*A21 -> 0 | C21: =C20 -> 0
A22: 10 | B22: =MB_UV*A22 -> 0 | C22: =C21 -> 0
A23: 11 | B23: =MB_UV*A23 -> 0 | C23: =C22 -> 0
A24: 12 | B24: =MB_UV*A24 -> 0 | C24: =C23 -> 0
A25: 13 | B25: =MB_UV*A25 -> 0 | C25: =C24 -> 0
... A50: 38 | B50: =MB_UV*A50 -> 0 | C50: =C49 -> 0
